Workbook

Sheet Model Inputs
B1: [Company Name]
B2: 5-Year Financial Plan—Manufacturing
B3: Model inputs and investor scenario
B5: Enter data in white cells only.
B6: Italicized numbers in gray cells are calculations that should not be overwritten.
B7: Non-italicized numbers in gray cells are calculations that can be overwritten.
B9: General notes and assumptions
B10: [Document key financial planning assumptions here.]
B19: Year 1 model inputs
B20: Use this area to capture key components of the Profit and Loss Statement and the Balance Sheet for the first year only.
B22: 1. Year-one revenue expectancy
C23: <Product 1> | D23: <Product 2> | E23: <Product 3> | F23: <Product 4>
B24: Number of units sold annually | C24: 2800 | D24: 1200 | E24: 1600 | F24: 0
B25: Average sales price per unit | C25: 120 | D25: 80 | E25: 40 | F25: 0
B26: Annual revenue per product | C26: =+C24*C25 -> 336000 | D26: =+D24*D25 -> 96000 | E26: =+E24*E25 -> 64000 | F26: =+F24*F25 -> 0
B28: Total year 1 revenue | C28: =SUM(C26:F26) -> 496000
B30: 2. Year 1 cost of goods sold
C31: =C23 -> <Product 1> | D31: =D23 -> <Product 2> | E31: =E23 -> <Product 3> | F31: =F23 -> <Product 4>
B32: Expected gross margin per product | C32: 0.5 | D32: 0.4 | E32: 0.25 | F32: 0
B33: Annual cost of goods sold per product | C33: =+C26*C32 -> 168000 | D33: =+D26*D32 -> 38400 | E33: =+E26*E32 -> 16000 | F33: =+F26*F32 -> 0
B35: Total year 1 cost of goods sold | C35: =SUM(C33:F33) -> 222400
B37: 3. Annual maintenance, repair, and overhaul
B38: Factor (%) on capital equipment | C38: 0.15
B40: 4. Number of years for straight-line depreciation | C40: 5
B42: 5. Annual tax rate | C42: 0.3
B44: 6. If long-term debt is being used to finance operations, enter the total loan value. | C44: 80000

Sheet Profit and Loss
B1: =+'Model Inputs'!B1 -> [Company Name]
B2: =+'Model Inputs'!B2 -> 5-Year Financial Plan—Manufacturing | F2: Annual cumulative price (revenue) increase rate | I2: 0.02
B3: Profit and loss projections | F3: Annual cumulative inflation (expense) increase rate | I3: 0.02
M5: Scenario Analysis- Year 2
B6: Year-by-year profit and loss assumptions
E7: Year 1 | F7: Year 2 | G7: Year 3 | H7: Year 4 | I7: Year 5
C8: Annual cumulative price (revenue) increase | E8: 0 | F8: =E8+$I$2 -> 0.02 | G8: =F8+$I$2 -> 0.04 | H8: =G8+$I$2 -> 0.06 | I8: =H8+$I$2 -> 0.08 | N8: Annual cumulative price (revenue) increase rate
C9: Annual cumulative inflation (expense) increase | E9: 0 | F9: =E9+$I$2 -> 0.02 | G9: =F9+$I$2 -> 0.04 | H9: =G9+$I$2 -> 0.06 | I9: =H9+$I$2 -> 0.08 | N9: 0.4 | O9: 0.3 | P9: 0.2 | Q9: 0.1 | R9: 0 | S9: -0.1 | T9: -0.2 | U9: -0.3 | V9: -0.4
C10: Interest rate on ending cash balance | E10: 0.005 | F10: 0.005 | G10: 0.005 | H10: 0.005 | I10: 0.005 | L10: Net income (loss)- | M10: =F48 -> 6276.4104 | N10: =O10*(1+N9) -> 0.048048 | O10: =P10*(1+O9) -> 0.03432 | P10: =Q10*(1+P9) -> 0.0264 | Q10: =R10*(1+Q9) -> 0.022 | R10: =$I$2 -> 0.02 | S10: =R10*(1+S9) -> 0.018 | T10: =S10*(1+T9) -> 0.0144 | U10: =T10*(1+U9) -> 0.01008 | V10: =U10*(1+V9) -> 0.006048
K11: Annual cumulative inflation (expense) increase rate | L11: 0.4 | M11: =M12*(1+L11) -> 0.048048 | N11: 6504.1602 | O11: 1737.7986 | P11: -1445.7506 | Q11: -3628.1506 | R11: -4620.1506 | S11: -5612.1506 | T11: -7397.7506 | U11: -9540.4706 | V11: -11540.343
L12: 0.3 | M12: =M13*(1+L12) -> 0.03432 | N12: 11159.05 | O12: 6392.6888 | P12: 3642.8648 | Q12: 2115.1848 | R12: 1420.7848 | S12: 726.38483 | T12: -747.90739 | U12: -2890.6274 | V12: -4890.4994
E13: =+E7 -> Year 1 | F13: =+F7 -> Year 2 | G13: =+G7 -> Year 3 | H13: =+H7 -> Year 4 | I13: =+I7 -> Year 5 | L13: 0.2 | M13: =M14*(1+L13) -> 0.0264 | N13: 13844.564 | O13: 9078.2024 | P13: 6328.3784 | Q13: 4800.6984 | R13: 4106.2984 | S13: 3411.8984 | T13: 2161.9784 | U13: 662.07443 | V13: -1054.0514
B14: Revenue | L14: 0.1 | M14: =M15*(1+L14) -> 0.022 | N14: 15336.516 | O14: 10570.154 | P14: 7820.3304 | Q14: 6292.6504 | R14: 5598.2504 | S14: 4903.8504 | T14: 3653.9304 | U14: 2154.0264 | V14: 754.11603
C15: Gross revenue | E15: =+'Model Inputs'!C28 -> 496000 | F15: =+E15*(1+F8) -> 505920 | G15: =+F15*(1+G8) -> 526156.8 | H15: =+G15*(1+H8) -> 557726.21 | I15: =+H15*(1+I8) -> 602344.3 | L15: 0 | M15: =$I$3 -> 0.02 | N15: 16014.676 | O15: 11248.314 | P15: 8498.4904 | Q15: 6970.8104 | R15: 6276.4104 | S15: 5582.0104 | T15: 4332.0904 | U15: 2832.1864 | V15: 1432.276
C16: Cost of goods sold | E16: =+'Model Inputs'!C35 -> 222400 | F16: =+E16*(1+F9) -> 226848 | G16: =+F16*(1+G9) -> 235921.92 | H16: =+G16*(1+H9) -> 250077.24 | I16: =+H16*(1+I9) -> 270083.41 | L16: -0.1 | M16: =M15*(1+L16) -> 0.018 | N16: 16692.836 | O16: 11926.474 | P16: 9176.6504 | Q16: 7648.9704 | R16: 6954.5704 | S16: 6260.1704 | T16: 5010.2504 | U16: 3510.3464 | V16: 2110.436
C17: Gross margin | E17: =E15-E16 -> 273600 | F17: =F15-F16 -> 279072 | G17: =G15-G16 -> 290234.88 | H17: =H15-H16 -> 307648.97 | I17: =I15-I16 -> 332260.89 | L17: -0.2 | M17: =M16*(1+L17) -> 0.0144 | N17: 17913.524 | O17: 13147.162 | P17: 10397.338 | Q17: 8869.6584 | R17: 8175.2584 | S17: 7480.8584 | T17: 6230.9384 | U17: 4731.0344 | V17: 3331.124
L18: -0.3 | M18: =M17*(1+L18) -> 0.01008 | N18: 19378.35 | O18: 14611.988 | P18: 11862.164 | Q18: 10334.484 | R18: 9640.084 | S18: 8945.684 | T18: 7695.764 | U18: 6195.86 | V18: 4795.9496
C19: Other revenue [source] | E19: 0 | F19: 0 | G19: 10000 | H19: 0 | I19: 0 | L19: -0.4 | M19: =M18*(1+L19) -> 0.006048 | N19: 20745.52 | O19: 15979.159 | P19: 13229.335 | Q19: 11701.655 | R19: 11007.255 | S19: 10312.855 | T19: 9062.9346 | U19: 7563.0306 | V19: 6163.1202
C20: Interest income | E20: 1000 | F20: 0 | G20: 0 | H20: 0 | I20: 0
C21: Total revenue | E21: =+E17+E19+E20 -> 274600 | F21: =+F17+F19+F20 -> 279072 | G21: =+G17+G19+G20 -> 300234.88 | H21: =+H17+H19+H20 -> 307648.97 | I21: =+I17+I19+I20 -> 332260.89
B23: Operating expenses
C24: Sales and marketing | E24: 40000 | F24: =+E24*(1+F$9) -> 40800 | G24: =+F24*(1+G$9) -> 42432 | H24: =+G24*(1+H$9) -> 44977.92 | I24: =+H24*(1+I$9) -> 48576.154
C25: Payroll and payroll taxes | E25: 60000 | F25: =+E25*(1+F$9) -> 61200 | G25: =+F25*(1+G$9) -> 63648 | H25: =+G25*(1+H$9) -> 67466.88 | I25: =+H25*(1+I$9) -> 72864.23
C26: Depreciation | E26: =('Balance Sheet'!D15+'Balance Sheet'!D17+'Balance Sheet'!D18)/'Model Inputs'!$C$40 -> 40000 | F26: =('Balance Sheet'!E15+'Balance Sheet'!E17+'Balance Sheet'!E18)/'Model Inputs'!$C$40*(1+F$9) -> 40800 | G26: =('Balance Sheet'!F15+'Balance Sheet'!F17+'Balance Sheet'!F18)/'Model Inputs'!$C$40*(1+G$9) -> 41600 | H26: =('Balance Sheet'!G15+'Balance Sheet'!G17+'Balance Sheet'!G18)/'Model Inputs'!$C$40*(1+H$9) -> 42400 | I26: =('Balance Sheet'!H15+'Balance Sheet'!H17+'Balance Sheet'!H18)/'Model Inputs'!$C$40*(1+I$9) -> 43200
C27: Insurance | E27: 40000 | F27: =+E27*(1+F$9) -> 40800 | G27: =+F27*(1+G$9) -> 42432 | H27: =+G27*(1+H$9) -> 44977.92 | I27: =+H27*(1+I$9) -> 48576.154
C28: Maintenance, repair, and overhaul | E28: =+'Balance Sheet'!D18*'Model Inputs'!$C$38 -> 15000 | F28: =('Balance Sheet'!E18*'Model Inputs'!$C$38)*(1+F$9) -> 15300 | G28: =('Balance Sheet'!F18*'Model Inputs'!$C$38)*(1+G$9) -> 15600 | H28: =('Balance Sheet'!G18*'Model Inputs'!$C$38)*(1+H$9) -> 15900 | I28: =('Balance Sheet'!H18*'Model Inputs'!$C$38)*(1+I$9) -> 16200
C29: Utilities | E29: 30000 | F29: =+E29*(1+F$9) -> 30600 | G29: =+F29*(1+G$9) -> 31824 | H29: =+G29*(1+H$9) -> 33733.44 | I29: =+H29*(1+I$9) -> 36432.115
C30: Property taxes | E30: 15000 | F30: =+E30*(1+F$9) -> 15300 | G30: =+F30*(1+G$9) -> 15912 | H30: =+G30*(1+H$9) -> 16866.72 | I30: =+H30*(1+I$9) -> 18216.058
C31: Administrative fees | E31: 18000 | F31: =+E31*(1+F$9) -> 18360 | G31: =+F31*(1+G$9) -> 19094.4 | H31: =+G31*(1+H$9) -> 20240.064 | I31: =+H31*(1+I$9) -> 21859.269
C32: Other | E32: 4000 | F32: =+E32*(1+F$9) -> 4080 | G32: =+F32*(1+G$9) -> 4243.2 | H32: =+G32*(1+H$9) -> 4497.792 | I32: =+H32*(1+I$9) -> 4857.6154
C33: Total operating expenses | E33: =SUM(E24:E32) -> 262000 | F33: =SUM(F24:F32) -> 267240 | G33: =SUM(G24:G32) -> 276785.6 | H33: =SUM(H24:H32) -> 291060.74 | I33: =SUM(I24:I32) -> 310781.59
B35: Operating income | E35: =E21-E33 -> 12600 | F35: =F21-F33 -> 11832 | G35: =G21-G33 -> 23449.28 | H35: =H21-H33 -> 16588.237 | I35: =I21-I33 -> 21479.296
C37: Interest expense on long-term debt | E37: =-SUM('Loan Payment Calculator'!F12:F23) -> 3589.5986 | F37: =-SUM('Loan Payment Calculator'!F24:F35) -> 2865.6994 | G37: =-SUM('Loan Payment Calculator'!F36:F47) -> 2105.6052 | H37: =-SUM('Loan Payment Calculator'!F48:F59) -> 1307.5064 | I37: =-SUM('Loan Payment Calculator'!F60:F71) -> 469.50258
B39: Operating income before other items | E39: =+E35-E37 -> 9010.4014 | F39: =+F35-F37 -> 8966.3006 | G39: =+G35-G37 -> 21343.675 | H39: =+H35-H37 -> 15280.73 | I39: =+I35-I37 -> 21009.793
C41: Loss (gain) on sale of assets | E41: 0 | F41: 0 | G41: 1000 | H41: 0 | I41: 0
C42: Other unusual expenses (income) | E42: 0 | F42: 0 | G42: 0 | H42: 0 | I42: 0
B44: Earnings before taxes | E44: =E39+E41+E42 -> 9010.4014 | F44: =F39+F41+F42 -> 8966.3006 | G44: =G39+G41+G42 -> 22343.675 | H44: =H39+H41+H42 -> 15280.73 | I44: =I39+I41+I42 -> 21009.793
B46: Taxes on income | D46: ='Model Inputs'!C42 -> 0.3 | E46: =IF(E44<0,0,$D$46*E44) -> 2703.1204 | F46: =IF(F44<0,0,$D$46*F44) -> 2689.8902 | G46: =IF(G44<0,0,$D$46*G44) -> 6703.1024 | H46: =IF(H44<0,0,$D$46*H44) -> 4584.2191 | I46: =IF(I44<0,0,$D$46*I44) -> 6302.9379
B48: Net income (loss) | E48: =E44-E46 -> 6307.281 | F48: =F44-F46 -> 6276.4104 | G48: =G44-G46 -> 15640.572 | H48: =H44-H46 -> 10696.511 | I48: =I44-I46 -> 14706.855
C51: Gross Profit Margin | E51: =(E15-E16)/E15 -> 0.5516129 | F51: =(F15-F16)/F15 -> 0.5516129 | G51: =(G15-G16)/G15 -> 0.5516129 | H51: =(H15-H16)/H15 -> 0.5516129 | I51: =(I15-I16)/I15 -> 0.5516129
...

Sheet Balance Sheet
B1: =+'Model Inputs'!B1 -> [Company Name]
B2: =+'Model Inputs'!B2 -> 5-Year Financial Plan—Manufacturing
B3: Balance sheet projections
B6: Assets | D6: Initial balance | E6: Year 1 | F6: Year 2 | G6: Year 3 | H6: Year 4 | I6: Year 5
C7: Cash and short-term investments | D7: 50000 | E7: =+'Cash Flow'!D36 -> 181829.3 | F7: =+'Cash Flow'!E36 -> 164703.82 | G7: =+'Cash Flow'!F36 -> 229982.42 | H7: =+'Cash Flow'!G36 -> 314818.85 | I7: =+'Cash Flow'!H36 -> 280127.63
C8: Accounts receivable | D8: 3000 | E8: =D8 -> 3000 | F8: =E8 -> 3000 | G8: =F8 -> 3000 | H8: =G8 -> 3000 | I8: =H8 -> 3000
C9: Total inventory | D9: 25000 | E9: =D9 -> 25000 | F9: =E9 -> 25000 | G9: =F9 -> 25000 | H9: =G9 -> 25000 | I9: =H9 -> 25000
C10: Prepaid expenses | D10: 0 | E10: =+D10 -> 0 | F10: =+E10 -> 0 | G10: =+F10 -> 0 | H10: =+G10 -> 0 | I10: =+H10 -> 0
C11: Deferred income tax | D11: 0 | E11: =+D11 -> 0 | F11: =+E11 -> 0 | G11: =+F11 -> 0 | H11: =+G11 -> 0 | I11: =+H11 -> 0
C12: Other current assets | D12: 5000 | E12: =+D12 -> 5000 | F12: =+E12 -> 5000 | G12: =+F12 -> 5000 | H12: =+G12 -> 5000 | I12: =+H12 -> 5000
C13: Total current assets | D13: =SUM(D7:D12) -> 83000 | E13: =SUM(E7:E12) -> 214829.3 | F13: =SUM(F7:F12) -> 197703.82 | G13: =SUM(G7:G12) -> 262982.42 | H13: =SUM(H7:H12) -> 347818.85 | I13: =SUM(I7:I12) -> 313127.63
C15: Buildings | D15: 100000 | E15: =+D15 -> 100000 | F15: =+E15 -> 100000 | G15: =+F15 -> 100000 | H15: =+G15 -> 100000 | I15: =+H15 -> 100000
C16: Land | D16: 100000 | E16: =+D16 -> 100000 | F16: =+E16 -> 100000 | G16: =+F16 -> 100000 | H16: =+G16 -> 100000 | I16: =+H16 -> 100000
C17: Capital improvements | D17: 0 | E17: =+D17 -> 0 | F17: =+E17 -> 0 | G17: =+F17 -> 0 | H17: =+G17 -> 0 | I17: =+H17 -> 0
C18: Machinery and equipment | D18: 100000 | E18: =D18 -> 100000 | F18: =E18 -> 100000 | G18: =F18 -> 100000 | H18: =G18 -> 100000 | I18: =H18 -> 100000
C19: Less: Accumulated depreciation expense | D19: 0 | E19: =+D19+'Profit and Loss'!E26 -> 40000 | F19: =+E19+'Profit and Loss'!F26 -> 80800 | G19: =+F19+'Profit and Loss'!G26 -> 122400 | H19: =+G19+'Profit and Loss'!H26 -> 164800 | I19: =+H19+'Profit and Loss'!I26 -> 208000
C20: Net property/equipment | D20: =SUM(D15:D18)-D19 -> 300000 | E20: =SUM(E15:E18)-E19 -> 260000 | F20: =SUM(F15:F18)-F19 -> 219200 | G20: =SUM(G15:G18)-G19 -> 177600 | H20: =SUM(H15:H18)-H19 -> 135200 | I20: =SUM(I15:I18)-I19 -> 92000
C22: Goodwill | D22: 0 | E22: =+D22 -> 0 | F22: =+E22 -> 0 | G22: =+F22 -> 0 | H22: =+G22 -> 0 | I22: =+H22 -> 0
C23: Deferred income tax | D23: 0 | E23: =+D23 -> 0 | F23: =+E23 -> 0 | G23: =+F23 -> 0 | H23: =+G23 -> 0 | I23: =+H23 -> 0
C24: Long-term investments | D24: 0 | E24: =+D24 -> 0 | F24: =+E24 -> 0 | G24: =+F24 -> 0 | H24: =+G24 -> 0 | I24: =+H24 -> 0
C25: Deposits | D25: 0 | E25: =+D25 -> 0 | F25: =+E25 -> 0 | G25: =+F25 -> 0 | H25: =+G25 -> 0 | I25: =+H25 -> 0
C26: Other long-term assets | D26: 0 | E26: =+D26 -> 0 | F26: =+E26 -> 0 | G26: =+F26 -> 0 | H26: =+G26 -> 0 | I26: =+H26 -> 0
C27: Total assets | D27: =SUM(D22:D26)+D20+D13 -> 383000 | E27: =SUM(E22:E26)+E20+E13 -> 474829.3 | F27: =SUM(F22:F26)+F20+F13 -> 416903.82 | G27: =SUM(G22:G26)+G20+G13 -> 440582.42 | H27: =SUM(H22:H26)+H20+H13 -> 483018.85 | I27: =SUM(I22:I26)+I20+I13 -> 405127.63
B29: Liabilities | D29: Initial balance | E29: =E6 -> Year 1 | F29: =F6 -> Year 2 | G29: =G6 -> Year 3 | H29: =H6 -> Year 4 | I29: =I6 -> Year 5
C30: Accounts payable | D30: 2000 | E30: =+D30 -> 2000 | F30: 3000 | G30: =+F30 -> 3000 | H30: 1500 | I30: =+H30 -> 1500
C31: Accrued expenses | D31: 0 | E31: =+D31 -> 0 | F31: =+E31 -> 0 | G31: =+F31 -> 0 | H31: =+G31 -> 0 | I31: =+H31 -> 0
C32: Notes payable/short-term debt | D32: 0 | E32: =+D32 -> 0 | F32: =+E32 -> 0 | G32: =+F32 -> 0 | H32: =+G32 -> 0 | I32: =+H32 -> 0
C33: Capital leases | D33: 0 | E33: =+D33 -> 0 | F33: =+E33 -> 0 | G33: =+F33 -> 0 | H33: =+G33 -> 0 | I33: =+H33 -> 0
C34: Other current liabilities | D34: 100 | E34: =+D34 -> 100 | F34: =+E34 -> 100 | G34: =+F34 -> 100 | H34: =+G34 -> 100 | I34: =+H34 -> 100
C35: Total current liabilities | D35: =SUM(D30:D34) -> 2100 | E35: =SUM(E30:E34) -> 2100 | F35: =SUM(F30:F34) -> 3100 | G35: =SUM(G30:G34) -> 3100 | H35: =SUM(H30:H34) -> 1600 | I35: =SUM(I30:I34) -> 1600
C37: Long-term debt from loan payment calculator | D37: =+'Model Inputs'!C44 -> 80000 | E37: ='Loan Payment Calculator'!D24 -> 65522.016 | F37: ='Loan Payment Calculator'!D36 -> 50320.133 | G37: ='Loan Payment Calculator'!D48 -> 34358.156 | H37: ='Loan Payment Calculator'!D60 -> 17598.08 | I37: ='Loan Payment Calculator'!D72 -> -5.3660187e-11
C38: Other long-term debt | D38: 100000 | E38: 200000 | F38: 150000 | G38: 175000 | H38: 225000 | I38: 150000
C39: Total debt | D39: =D35+D37+D38 -> 182100 | E39: =E35+E37+E38 -> 267622.02 | F39: =F35+F37+F38 -> 203420.13 | G39: =G35+G37+G38 -> 212458.16 | H39: =H35+H37+H38 -> 244198.08 | I39: =I35+I37+I38 -> 151600
C41: Other liabilities | D41: 0 | E41: =+D41 -> 0 | F41: =+E41 -> 0 | G41: =+F41 -> 0 | H41: =+G41 -> 0 | I41: =+H41 -> 0
C43: Total liabilities | D43: =D35+D37+D41 -> 82100 | E43: =E35+E37+E41 -> 67622.016 | F43: =F35+F37+F41 -> 53420.133 | G43: =G35+G37+G41 -> 37458.156 | H43: =H35+H37+H41 -> 19198.08 | I43: =I35+I37+I41 -> 1600
B45: Equity | D45: Initial balance | E45: =E6 -> Year 1 | F45: =F6 -> Year 2 | G45: =G6 -> Year 3 | H45: =H6 -> Year 4 | I45: =I6 -> Year 5
C46: Owner's equity (common) | D46: 50000 | E46: =D46 -> 50000 | F46: =E46 -> 50000 | G46: =F46 -> 50000 | H46: =G46 -> 50000 | I46: =H46 -> 50000
C47: Paid-in capital | D47: 250000 | E47: =+D47 -> 250000 | F47: =E47 -> 250000 | G47: =F47 -> 250000 | H47: =G47 -> 250000 | I47: =H47 -> 250000
C48: Preferred equity | D48: 0 | E48: =+D48 -> 0 | F48: =E48 -> 0 | G48: =F48 -> 0 | H48: =G48 -> 0 | I48: =H48 -> 0
C49: Retained earnings | D49: 0 | E49: =+'Profit and Loss'!E48 -> 6307.281 | F49: =+E49+'Profit and Loss'!F48 -> 12583.691 | G49: =+F49+'Profit and Loss'!G48 -> 28224.264 | H49: =+G49+'Profit and Loss'!H48 -> 38920.775 | I49: =+H49+'Profit and Loss'!I48 -> 53627.63
...

Sheet Cash Flow
B1: =+'Model Inputs'!B1 -> [Company Name]
B2: =+'Model Inputs'!B2 -> 5-Year Financial Plan—Manufacturing
B3: Cash flow
D6: Year 1 | E6: Year 2 | F6: Year 3 | G6: Year 4 | H6: Year 5 | I6: Total
B7: Operating activities
C8: Net income | D8: =+'Profit and Loss'!E48 -> 6307.281 | E8: =+'Profit and Loss'!F48 -> 6276.4104 | F8: =+'Profit and Loss'!G48 -> 15640.572 | G8: =+'Profit and Loss'!H48 -> 10696.511 | H8: =+'Profit and Loss'!I48 -> 14706.855 | I8: =SUM(D8:H8) -> 53627.63
C9: Depreciation | D9: ='Profit and Loss'!E26 -> 40000 | E9: ='Profit and Loss'!F26 -> 40800 | F9: ='Profit and Loss'!G26 -> 41600 | G9: ='Profit and Loss'!H26 -> 42400 | H9: ='Profit and Loss'!I26 -> 43200 | I9: =SUM(D9:H9) -> 208000
C10: Accounts receivable | D10: =+'Balance Sheet'!D8-'Balance Sheet'!E8 -> 0 | E10: =+'Balance Sheet'!E8-'Balance Sheet'!F8 -> 0 | F10: =+'Balance Sheet'!F8-'Balance Sheet'!G8 -> 0 | G10: =+'Balance Sheet'!G8-'Balance Sheet'!H8 -> 0 | H10: =+'Balance Sheet'!H8-'Balance Sheet'!I8 -> 0 | I10: =SUM(D10:H10) -> 0
C11: Inventories | D11: =+'Balance Sheet'!D9-'Balance Sheet'!E9 -> 0 | E11: =+'Balance Sheet'!E9-'Balance Sheet'!F9 -> 0 | F11: =+'Balance Sheet'!F9-'Balance Sheet'!G9 -> 0 | G11: =+'Balance Sheet'!G9-'Balance Sheet'!H9 -> 0 | H11: =+'Balance Sheet'!H9-'Balance Sheet'!I9 -> 0 | I11: =SUM(D11:H11) -> 0
C12: Accounts payable | D12: =+'Balance Sheet'!E30-'Balance Sheet'!D30 -> 0 | E12: =+'Balance Sheet'!F30-'Balance Sheet'!E30 -> 1000 | F12: =+'Balance Sheet'!G30-'Balance Sheet'!F30 -> 0 | G12: =+'Balance Sheet'!H30-'Balance Sheet'!G30 -> -1500 | H12: =+'Balance Sheet'!I30-'Balance Sheet'!H30 -> 0 | I12: =SUM(D12:H12) -> -500
C13: Amortization | D13: 0 | E13: =D13 -> 0 | F13: =E13 -> 0 | G13: =F13 -> 0 | H13: =G13 -> 0 | I13: =SUM(D13:H13) -> 0
C14: Other liabilities | D14: 0 | E14: =D14 -> 0 | F14: =E14 -> 0 | G14: =F14 -> 0 | H14: =G14 -> 0 | I14: =SUM(D14:H14) -> 0
C15: Other operating cash flow items | D15: 0 | E15: =D15 -> 0 | F15: =E15 -> 0 | G15: =F15 -> 0 | H15: =G15 -> 0 | I15: =SUM(D15:H15) -> 0
C16: Total operating activities | D16: =SUM(D8:D15) -> 46307.281 | E16: =SUM(E8:E15) -> 48076.41 | F16: =SUM(F8:F15) -> 57240.572 | G16: =SUM(G8:G15) -> 51596.511 | H16: =SUM(H8:H15) -> 57906.855 | I16: =SUM(D16:H16) -> 261127.63
B18: Investing activities
C19: Capital expenditures | D19: =-1 * MAX(0,SUM('Balance Sheet'!E15:E18)-SUM('Balance Sheet'!D15:D18)) -> 0 | E19: =-1 * MAX(0,SUM('Balance Sheet'!F15:F18)-SUM('Balance Sheet'!E15:E18)) -> 0 | F19: =-1 * MAX(0,SUM('Balance Sheet'!G15:G18)-SUM('Balance Sheet'!F15:F18)) -> 0 | G19: =-1 * MAX(0,SUM('Balance Sheet'!H15:H18)-SUM('Balance Sheet'!G15:G18)) -> 0 | H19: =-1 * MAX(0,SUM('Balance Sheet'!I15:I18)-SUM('Balance Sheet'!H15:H18)) -> 0 | I19: =SUM(D19:H19) -> 0
C20: Acquisition of business | D20: 0 | E20: 0 | F20: 0 | G20: 0 | H20: 0 | I20: =SUM(D20:H20) -> 0
C21: Sale of fixed assets | D21: =(-1*MIN(0,SUM('Balance Sheet'!E15:E18)-SUM('Balance Sheet'!D15:D18))-'Profit and Loss'!E41) -> 0 | E21: =(-1*MIN(0,SUM('Balance Sheet'!F15:F18)-SUM('Balance Sheet'!E15:E18))-'Profit and Loss'!F41) -> 0 | F21: =(-1*MIN(0,SUM('Balance Sheet'!G15:G18)-SUM('Balance Sheet'!F15:F18))-'Profit and Loss'!G41) -> -1000 | G21: =(-1*MIN(0,SUM('Balance Sheet'!H15:H18)-SUM('Balance Sheet'!G15:G18))-'Profit and Loss'!H41) -> 0 | H21: =(-1*MIN(0,SUM('Balance Sheet'!I15:I18)-SUM('Balance Sheet'!H15:H18))-'Profit and Loss'!I41) -> 0 | I21: =SUM(D21:H21) -> -1000
C22: Other investing cash flow items | D22: 0 | E22: 0 | F22: 0 | G22: 0 | H22: 0 | I22: =SUM(D22:H22) -> 0
C23: Total investing activities | D23: =SUM(D19:D22) -> 0 | E23: =SUM(E19:E22) -> 0 | F23: =SUM(F19:F22) -> -1000 | G23: =SUM(G19:G22) -> 0 | H23: =SUM(H19:H22) -> 0 | I23: =SUM(D23:H23) -> -1000
B25: Financing activities
C26: Long-term debt/financing | D26: ='Balance Sheet'!E37+'Balance Sheet'!E38-('Balance Sheet'!D37+'Balance Sheet'!D38) -> 85522.016 | E26: ='Balance Sheet'!F37+'Balance Sheet'!F38-('Balance Sheet'!E37+'Balance Sheet'!E38) -> -65201.883 | F26: ='Balance Sheet'!G37+'Balance Sheet'!G38-('Balance Sheet'!F37+'Balance Sheet'!F38) -> 9038.0228 | G26: ='Balance Sheet'!H37+'Balance Sheet'!H38-('Balance Sheet'!G37+'Balance Sheet'!G38) -> 33239.924 | H26: ='Balance Sheet'!I37+'Balance Sheet'!I38-('Balance Sheet'!H37+'Balance Sheet'!H38) -> -92598.08 | I26: =SUM(D26:H26) -> -30000
C27: Preferred stock | D27: 0 | E27: =D27 -> 0 | F27: =E27 -> 0 | G27: =F27 -> 0 | H27: =G27 -> 0 | I27: =SUM(D27:H27) -> 0
C28: Total cash dividends paid | D28: 0 | E28: =D28 -> 0 | F28: =E28 -> 0 | G28: =F28 -> 0 | H28: =G28 -> 0 | I28: =SUM(D28:H28) -> 0
C29: Common stock | D29: 0 | E29: =D29 -> 0 | F29: =E29 -> 0 | G29: =F29 -> 0 | H29: =G29 -> 0 | I29: =SUM(D29:H29) -> 0
C30: Other financing cash flow items | D30: 0 | E30: =D30 -> 0 | F30: =E30 -> 0 | G30: =F30 -> 0 | H30: =G30 -> 0 | I30: =SUM(D30:H30) -> 0
C31: Total financing activities | D31: =SUM(D26:D30) -> 85522.016 | E31: =SUM(E26:E30) -> -65201.883 | F31: =SUM(F26:F30) -> 9038.0228 | G31: =SUM(G26:G30) -> 33239.924 | H31: =SUM(H26:H30) -> -92598.08 | I31: =SUM(D31:H31) -> -30000
B33: Cumulative cash flow | D33: =D16+D23+D31 -> 131829.3 | E33: =E16+E23+E31 -> -17125.473 | F33: =F16+F23+F31 -> 65278.595 | G33: =G16+G23+G31 -> 84836.435 | H33: =H16+H23+H31 -> -34691.225 | I33: =SUM(D33:H33) -> 230127.63
B35: Beginning cash balance | D35: =+'Balance Sheet'!D7 -> 50000 | E35: =D36 -> 181829.3 | F35: =E36 -> 164703.82 | G35: =F36 -> 229982.42 | H35: =G36 -> 314818.85
B36: Ending cash balance | D36: =D35+D33 -> 181829.3 | E36: =E35+E33 -> 164703.82 | F36: =F35+F33 -> 229982.42 | G36: =G35+G33 -> 314818.85 | H36: =H35+H33 -> 280127.63
C40: Operating Cash Flow Margin | D40: =D16/'Profit and Loss'!E15 -> 0.093361454 | E40: =E16/'Profit and Loss'!F15 -> 0.095027693 | F40: =F16/'Profit and Loss'!G15 -> 0.10878995 | G40: =G16/'Profit and Loss'!H15 -> 0.092512259 | H40: =H16/'Profit and Loss'!I15 -> 0.096135806

Sheet Loan Payment Calculator
B1: =+'Model Inputs'!B1 -> [Company Name]
B2: =+'Model Inputs'!B2 -> 5-Year Financial Plan—Manufacturing
B3: Loan payment calculator
B5: Annual interest rate | C5: 0.05 | E5: Note: This calculator can generate principal and interest payments for a period of up to 30 years (360 months).
B6: Monthly rate | C6: =(1+C5)^(1/12)-1 -> 0.0040741238
B7: Loan amount | C7: =+'Model Inputs'!C44 -> 80000
B8: Term of loan (months) | C8: 60
B9: Payment | C9: =PMT(C6,C8,C7) -> -1505.6319
C11: Month | D11: Principal balance | E11: Principal payment | F11: Interest | G11: Payment
C12: 1 | D12: =C7 -> 80000 | E12: =G12-F12 -> -1179.702 | F12: =-$C$6*D12 -> -325.9299 | G12: =IF(C12>$C$8, 0, $C$9) -> -1505.6319
C13: 2 | D13: =D12+E12 -> 78820.298 | E13: =G13-F13 -> -1184.5082 | F13: =-$C$6*D13 -> -321.12365 | G13: =IF(C13>$C$8, 0, $C$9) -> -1505.6319
C14: 3 | D14: =D13+E13 -> 77635.79 | E14: =G14-F14 -> -1189.3341 | F14: =-$C$6*D14 -> -316.29782 | G14: =IF(C14>$C$8, 0, $C$9) -> -1505.6319
C15: 4 | D15: =D14+E14 -> 76446.456 | E15: =G15-F15 -> -1194.1795 | F15: =-$C$6*D15 -> -311.45232 | G15: =IF(C15>$C$8, 0, $C$9) -> -1505.6319
C16: 5 | D16: =D15+E15 -> 75252.276 | E16: =G16-F16 -> -1199.0448 | F16: =-$C$6*D16 -> -306.58709 | G16: =IF(C16>$C$8, 0, $C$9) -> -1505.6319
C17: 6 | D17: =D16+E16 -> 74053.231 | E17: =G17-F17 -> -1203.9298 | F17: =-$C$6*D17 -> -301.70203 | G17: =IF(C17>$C$8, 0, $C$9) -> -1505.6319
C18: 7 | D18: =D17+E17 -> 72849.302 | E18: =G18-F18 -> -1208.8348 | F18: =-$C$6*D18 -> -296.79707 | G18: =IF(C18>$C$8, 0, $C$9) -> -1505.6319
C19: 8 | D19: =D18+E18 -> 71640.467 | E19: =G19-F19 -> -1213.7597 | F19: =-$C$6*D19 -> -291.87213 | G19: =IF(C19>$C$8, 0, $C$9) -> -1505.6319
C20: 9 | D20: =D19+E19 -> 70426.707 | E20: =G20-F20 -> -1218.7047 | F20: =-$C$6*D20 -> -286.92712 | G20: =IF(C20>$C$8, 0, $C$9) -> -1505.6319
C21: 10 | D21: =D20+E20 -> 69208.002 | E21: =G21-F21 -> -1223.6699 | F21: =-$C$6*D21 -> -281.96197 | G21: =IF(C21>$C$8, 0, $C$9) -> -1505.6319
C22: 11 | D22: =D21+E21 -> 67984.332 | E22: =G22-F22 -> -1228.6553 | F22: =-$C$6*D22 -> -276.97659 | G22: =IF(C22>$C$8, 0, $C$9) -> -1505.6319
C23: 12 | D23: =D22+E22 -> 66755.677 | E23: =G23-F23 -> -1233.661 | F23: =-$C$6*D23 -> -271.97089 | G23: =IF(C23>$C$8, 0, $C$9) -> -1505.6319
C24: 13 | D24: =D23+E23 -> 65522.016 | E24: =G24-F24 -> -1238.6871 | F24: =-$C$6*D24 -> -266.9448 | G24: =IF(C24>$C$8, 0, $C$9) -> -1505.6319
... C371: 360 | D371: =D370+E370 -> -1.8097513e-10 | E371: =G371-F371 -> -7.3731506e-13 | F371: =-$C$6*D371 -> 7.3731506e-13 | G371: =IF(C371>$C$8, 0, $C$9) -> 0
